start for Bill Gates
No file exists. Creating a new one.
Creating a new Dictionary
0 100  ----  0 0
Traceback (most recent call last):
  File "C:\Users\Bhavya\Desktop\Vaibhav\Django-projects\recallie_web\news\utils.py", line 322, in load_useful100
    with open(path, 'rb') as fp:
FileNotFoundError: [Errno 2] No such file or directory: 'data/dumps/Bill Gates_useful100.pkl'

During handling of the above exception, another exception occurred:

Traceback (most recent call last):
  File "make_dumps.py", line 22, in <module>
    print(load_useful100(query))
  File "C:\Users\Bhavya\Desktop\Vaibhav\Django-projects\recallie_web\news\utils.py", line 326, in load_useful100
    useful100 = make_useful100(query)
  File "C:\Users\Bhavya\Desktop\Vaibhav\Django-projects\recallie_web\news\utils.py", line 262, in make_useful100
    MERGED_DF = pd.concat(DFs, ignore_index=True)
  File "c:\Users\Bhavya\Anaconda3\lib\site-packages\pandas\core\reshape\concat.py", line 228, in concat
    copy=copy, sort=sort)
  File "c:\Users\Bhavya\Anaconda3\lib\site-packages\pandas\core\reshape\concat.py", line 262, in __init__
    raise ValueError('No objects to concatenate')
ValueError: No objects to concatenate
sys:1: ResourceWarning: unclosed <socket.socket fd=1560, family=AddressFamily.AF_INET, type=SocketKind.SOCK_STREAM, proto=0, laddr=('127.0.0.1', 49888), raddr=('127.0.0.1', 49883)>
Saved
c:\Users\Bhavya\Anaconda3\lib\site-packages\bs4\builder\_lxml.py:208: ResourceWarning: unclosed <socket.socket fd=1440, family=AddressFamily.AF_INET, type=SocketKind.SOCK_STREAM, proto=0, laddr=('127.0.0.1', 49954), raddr=('127.0.0.1', 49949)>
  for attr, value in list(attrs.items()):
start for Bill Gates
{}
No file exists. Creating a new one.
Creating a new Dictionary
0 100  ----  0 0
Traceback (most recent call last):
  File "C:\Users\Bhavya\Desktop\Vaibhav\Django-projects\recallie_web\news\utils.py", line 322, in load_useful100
    with open(path, 'rb') as fp:
FileNotFoundError: [Errno 2] No such file or directory: 'data/dumps/Bill Gates_useful100.pkl'

During handling of the above exception, another exception occurred:

Traceback (most recent call last):
  File "make_dumps.py", line 23, in <module>
    print(load_useful100(query))
  File "C:\Users\Bhavya\Desktop\Vaibhav\Django-projects\recallie_web\news\utils.py", line 326, in load_useful100
    useful100 = make_useful100(query)
  File "C:\Users\Bhavya\Desktop\Vaibhav\Django-projects\recallie_web\news\utils.py", line 262, in make_useful100
    MERGED_DF = pd.concat(DFs, ignore_index=True)
  File "c:\Users\Bhavya\Anaconda3\lib\site-packages\pandas\core\reshape\concat.py", line 228, in concat
    copy=copy, sort=sort)
  File "c:\Users\Bhavya\Anaconda3\lib\site-packages\pandas\core\reshape\concat.py", line 262, in __init__
    raise ValueError('No objects to concatenate')
ValueError: No objects to concatenate
sys:1: ResourceWarning: unclosed <socket.socket fd=1796, family=AddressFamily.AF_INET, type=SocketKind.SOCK_STREAM, proto=0, laddr=('127.0.0.1', 49992), raddr=('127.0.0.1', 49986)>
Saved
